Workbook

Sheet RAW DATA
A1: Date | B1: Year | C1: Month | D1: Week | E1: SKU | F1: Product_Name | G1: Category | H1: Units_Sold | I1: Revenue | J1: Unit_Price | K1: Promotion | L1: Stockout | M1: Extract Month
A2: 44927 | B2: 2023 | C2: 1 | D2: 52 | E2: SKU-1001 | F2: Bathroom Tissue 12pk | G2: Tissue | H2: 410 | I2: 5325.9 | J2: 12.99 | K2: No | L2: No | M2: =TEXT(A2,"MMM") -> Jan
A3: 44927 | B3: 2023 | C3: 1 | D3: 52 | E3: SKU-1002 | F3: Paper Towels 6pk | G3: Paper Towels | H3: 266 | I3: 4120.34 | J3: 15.49 | K3: No | L3: No | M3: Jan
A4: 44927 | B4: 2023 | C4: 1 | D4: 52 | E4: SKU-1003 | F4: Facial Tissue Box | G4: Facial Tissue | H4: 412 | I4: 1643.88 | J4: 3.99 | K4: Yes | L4: No | M4: Jan
A5: 44927 | B5: 2023 | C5: 1 | D5: 52 | E5: SKU-1004 | F5: Napkins 200ct | G5: Napkins | H5: 180 | I5: 808.2 | J5: 4.49 | K5: No | L5: No | M5: Jan
A6: 44927 | B6: 2023 | C6: 1 | D6: 52 | E6: SKU-1005 | F6: Kitchen Rolls 3pk | G6: Paper Towels | H6: 189 | I6: 1699.11 | J6: 8.99 | K6: No | L6: No | M6: Jan
A7: 45139 | B7: 2023 | C7: 1 | D7: 1 | E7: SKU-1001 | F7: Bathroom Tissue 12pk | G7: Tissue | H7: 356 | I7: 4624.44 | J7: 12.99 | K7: No | L7: No | M7: Jan
A8: 45139 | B8: 2023 | C8: 1 | D8: 1 | E8: SKU-1002 | F8: Paper Towels 6pk | G8: Paper Towels | H8: 230 | I8: 3562.7 | J8: 15.49 | K8: No | L8: No | M8: Jan
A9: 45139 | B9: 2023 | C9: 1 | D9: 1 | E9: SKU-1003 | F9: Facial Tissue Box | G9: Facial Tissue | H9: 249 | I9: 993.51 | J9: 3.99 | K9: No | L9: No | M9: Jan
A10: 45139 | B10: 2023 | C10: 1 | D10: 1 | E10: SKU-1004 | F10: Napkins 200ct | G10: Napkins | H10: 48 | I10: 215.52 | J10: 4.49 | K10: No | L10: Yes | M10: Jan
A11: 45139 | B11: 2023 | C11: 1 | D11: 1 | E11: SKU-1005 | F11: Kitchen Rolls 3pk | G11: Paper Towels | H11: 160 | I11: 1438.4 | J11: 8.99 | K11: No | L11: No | M11: Jan
A12: 1/15/2023 | B12: 2023 | C12: 1 | D12: 2 | E12: SKU-1001 | F12: Bathroom Tissue 12pk | G12: Tissue | H12: 348 | I12: 4520.52 | J12: 12.99 | K12: No | L12: No | M12: Jan
A13: 1/15/2023 | B13: 2023 | C13: 1 | D13: 2 | E13: SKU-1002 | F13: Paper Towels 6pk | G13: Paper Towels | H13: 364 | I13: 5638.36 | J13: 15.49 | K13: Yes | L13: No | M13: Jan
A14: 1/15/2023 | B14: 2023 | C14: 1 | D14: 2 | E14: SKU-1003 | F14: Facial Tissue Box | G14: Facial Tissue | H14: 267 | I14: 1065.33 | J14: 3.99 | K14: No | L14: No | M14: Jan
A15: 1/15/2023 | B15: 2023 | C15: 1 | D15: 2 | E15: SKU-1004 | F15: Napkins 200ct | G15: Napkins | H15: 132 | I15: 592.68 | J15: 4.49 | K15: No | L15: No | M15: Jan
A16: 1/15/2023 | B16: 2023 | C16: 1 | D16: 2 | E16: SKU-1005 | F16: Kitchen Rolls 3pk | G16: Paper Towels | H16: 317 | I16: 2849.83 | J16: 8.99 | K16: Yes | L16: No | M16: Jan
A17: 1/22/2023 | B17: 2023 | C17: 1 | D17: 3 | E17: SKU-1001 | F17: Bathroom Tissue 12pk | G17: Tissue | H17: 550 | I17: 7144.5 | J17: 12.99 | K17: Yes | L17: No | M17: Jan
A18: 1/22/2023 | B18: 2023 | C18: 1 | D18: 3 | E18: SKU-1002 | F18: Paper Towels 6pk | G18: Paper Towels | H18: 212 | I18: 3283.88 | J18: 15.49 | K18: No | L18: No | M18: Jan
A19: 1/22/2023 | B19: 2023 | C19: 1 | D19: 3 | E19: SKU-1003 | F19: Facial Tissue Box | G19: Facial Tissue | H19: 212 | I19: 845.88 | J19: 3.99 | K19: No | L19: No | M19: Jan
A20: 1/22/2023 | B20: 2023 | C20: 1 | D20: 3 | E20: SKU-1004 | F20: Napkins 200ct | G20: Napkins | H20: 237 | I20: 1064.13 | J20: 4.49 | K20: Yes | L20: No | M20: Jan
A21: 1/22/2023 | B21: 2023 | C21: 1 | D21: 3 | E21: SKU-1005 | F21: Kitchen Rolls 3pk | G21: Paper Towels | H21: 192 | I21: 1726.08 | J21: 8.99 | K21: No | L21: No | M21: Jan
A22: 1/29/2023 | B22: 2023 | C22: 1 | D22: 4 | E22: SKU-1001 | F22: Bathroom Tissue 12pk | G22: Tissue | H22: 443 | I22: 5754.57 | J22: 12.99 | K22: No | L22: No | M22: Jan
A23: 1/29/2023 | B23: 2023 | C23: 1 | D23: 4 | E23: SKU-1002 | F23: Paper Towels 6pk | G23: Paper Towels | H23: 311 | I23: 4817.39 | J23: 15.49 | K23: No | L23: No | M23: Jan
... A26: 1/29/2023 | B26: 2023 | C26: 1 | D26: 4 | E26: SKU-1005 | F26: Kitchen Rolls 3pk | G26: Paper Towels | H26: 229 | I26: 2058.71 | J26: 8.99 | K26: No | L26: No | M26: Jan
A27: 45048 | B27: 2023 | C27: 2 | D27: 5 | E27: SKU-1001 | F27: Bathroom Tissue 12pk | G27: Tissue | H27: 761 | I27: 9885.39 | J27: 12.99 | K27: Yes | L27: No | M27: Feb
A28: 45048 | B28: 2023 | C28: 2 | D28: 5 | E28: SKU-1002 | F28: Paper Towels 6pk | G28: Paper Towels | H28: 339 | I28: 5251.11 | J28: 15.49 | K28: No | L28: No | M28: Feb
A29: 45048 | B29: 2023 | C29: 2 | D29: 5 | E29: SKU-1003 | F29: Facial Tissue Box | G29: Facial Tissue | H29: 346 | I29: 1380.54 | J29: 3.99 | K29: No | L29: No | M29: Feb
A30: 45048 | B30: 2023 | C30: 2 | D30: 5 | E30: SKU-1004 | F30: Napkins 200ct | G30: Napkins | H30: 193 | I30: 866.57 | J30: 4.49 | K30: No | L30: No | M30: Feb
A31: 45048 | B31: 2023 | C31: 2 | D31: 5 | E31: SKU-1005 | F31: Kitchen Rolls 3pk | G31: Paper Towels | H31: 230 | I31: 2067.7 | J31: 8.99 | K31: No | L31: No | M31: Feb
A32: 45262 | B32: 2023 | C32: 2 | D32: 6 | E32: SKU-1001 | F32: Bathroom Tissue 12pk | G32: Tissue | H32: 553 | I32: 7183.47 | J32: 12.99 | K32: No | L32: No | M32: Feb
A33: 45262 | B33: 2023 | C33: 2 | D33: 6 | E33: SKU-1002 | F33: Paper Towels 6pk | G33: Paper Towels | H33: 296 | I33: 4585.04 | J33: 15.49 | K33: No | L33: No | M33: Feb
A34: 45262 | B34: 2023 | C34: 2 | D34: 6 | E34: SKU-1003 | F34: Facial Tissue Box | G34: Facial Tissue | H34: 320 | I34: 1276.8 | J34: 3.99 | K34: No | L34: No | M34: Feb
A35: 45262 | B35: 2023 | C35: 2 | D35: 6 | E35: SKU-1004 | F35: Napkins 200ct | G35: Napkins | H35: 200 | I35: 898 | J35: 4.49 | K35: No | L35: No | M35: Feb
A36: 45262 | B36: 2023 | C36: 2 | D36: 6 | E36: SKU-1005 | F36: Kitchen Rolls 3pk | G36: Paper Towels | H36: 216 | I36: 1941.84 | J36: 8.99 | K36: No | L36: No | M36: Feb
A37: 2/19/2023 | B37: 2023 | C37: 2 | D37: 7 | E37: SKU-1001 | F37: Bathroom Tissue 12pk | G37: Tissue | H37: 430 | I37: 5585.7 | J37: 12.99 | K37: No | L37: No | M37: Feb
A38: 2/19/2023 | B38: 2023 | C38: 2 | D38: 7 | E38: SKU-1002 | F38: Paper Towels 6pk | G38: Paper Towels | H38: 322 | I38: 4987.78 | J38: 15.49 | K38: No | L38: No | M38: Feb
A39: 2/19/2023 | B39: 2023 | C39: 2 | D39: 7 | E39: SKU-1003 | F39: Facial Tissue Box | G39: Facial Tissue | H39: 380 | I39: 1516.2 | J39: 3.99 | K39: Yes | L39: No | M39: Feb
A40: 2/19/2023 | B40: 2023 | C40: 2 | D40: 7 | E40: SKU-1004 | F40: Napkins 200ct | G40: Napkins | H40: 186 | I40: 835.14 | J40: 4.49 | K40: No | L40: No | M40: Feb
A41: 2/19/2023 | B41: 2023 | C41: 2 | D41: 7 | E41: SKU-1005 | F41: Kitchen Rolls 3pk | G41: Paper Towels | H41: 256 | I41: 2301.44 | J41: 8.99 | K41: No | L41: No | M41: Feb
A42: 2/26/2023 | B42: 2023 | C42: 2 | D42: 8 | E42: SKU-1001 | F42: Bathroom Tissue 12pk | G42: Tissue | H42: 96 | I42: 1247.04 | J42: 12.99 | K42: No | L42: Yes | M42: Feb
...

Sheet PHASE 1
A1: SKU | B1: Total Sales by SKU | C1: Average Weekly Sales (Non-Promo) | D1: Average Weekly Sales (With Promo) | E1: Promotional Lift % | F1: Count of Stockouts
A2: SKU-1001 | B2: =SUMIFS('RAW DATA'!H:H,'RAW DATA'!E:E,A2) -> 54076 | C2: =AVERAGEIFS('RAW DATA'!H:H,'RAW DATA'!E:E,A2,'RAW DATA'!K:K,"No") -> 486.4 | D2: =AVERAGEIFS('RAW DATA'!H:H,'RAW DATA'!E:E,A2,'RAW DATA'!K:K,"Yes") -> 670.10526 | E2: =(D2-C2)/C2 -> 0.37768352 | F2: =COUNTIFS('RAW DATA'!E:E,A2,'RAW DATA'!L:L,"Yes") -> 3
A3: SKU-1002 | B3: =SUMIFS('RAW DATA'!H:H,'RAW DATA'!E:E,A3) -> 37356 | C3: =AVERAGEIFS('RAW DATA'!H:H,'RAW DATA'!E:E,A3,'RAW DATA'!K:K,"No") -> 337.68966 | D3: =AVERAGEIFS('RAW DATA'!H:H,'RAW DATA'!E:E,A3,'RAW DATA'!K:K,"Yes") -> 469.23529 | E3: =(D3-C3)/C3 -> 0.38954595 | F3: =COUNTIFS('RAW DATA'!E:E,A3,'RAW DATA'!L:L,"Yes") -> 5
A4: SKU-1003 | B4: =SUMIFS('RAW DATA'!H:H,'RAW DATA'!E:E,A4) -> 33573 | C4: =AVERAGEIFS('RAW DATA'!H:H,'RAW DATA'!E:E,A4,'RAW DATA'!K:K,"No") -> 296.13924 | D4: =AVERAGEIFS('RAW DATA'!H:H,'RAW DATA'!E:E,A4,'RAW DATA'!K:K,"Yes") -> 407.12 | E4: =(D4-C4)/C4 -> 0.37475871 | F4: =COUNTIFS('RAW DATA'!E:E,A4,'RAW DATA'!L:L,"Yes") -> 5
A5: SKU-1004 | B5: =SUMIFS('RAW DATA'!H:H,'RAW DATA'!E:E,A5) -> 21599 | C5: =AVERAGEIFS('RAW DATA'!H:H,'RAW DATA'!E:E,A5,'RAW DATA'!K:K,"No") -> 191.91954 | D5: =AVERAGEIFS('RAW DATA'!H:H,'RAW DATA'!E:E,A5,'RAW DATA'!K:K,"Yes") -> 288.35294 | E5: =(D5-C5)/C5 -> 0.50246786 | F5: =COUNTIFS('RAW DATA'!E:E,A5,'RAW DATA'!L:L,"Yes") -> 10
A6: SKU-1005 | B6: =SUMIFS('RAW DATA'!H:H,'RAW DATA'!E:E,A6) -> 28687 | C6: =AVERAGEIFS('RAW DATA'!H:H,'RAW DATA'!E:E,A6,'RAW DATA'!K:K,"No") -> 254.30682 | D6: =AVERAGEIFS('RAW DATA'!H:H,'RAW DATA'!E:E,A6,'RAW DATA'!K:K,"Yes") -> 394.25 | E6: =(D6-C6)/C6 -> 0.55029269 | F6: =COUNTIFS('RAW DATA'!E:E,A6,'RAW DATA'!L:L,"Yes") -> 2

Sheet PHASE 2
A1: Date | B1: Year | C1: Month | D1: Week | E1: Historical Sale SKU-1001 | F1: Historical Sale SKU-1002 | G1: Historical Sale SKU-1003 | H1: Historical Sale SKU-1004 | I1: Historical Sale SKU-1005 | J1: Seasonal index SKU-1001 | K1: Seasonal index SKU-1002 | L1: Seasonal index SKU-1003 | M1: Seasonal index SKU-1004 | N1: Seasonal index SKU-1005 | O1: Deseasonalized SKU-1001 | P1: Deseasonalized SKU-1002 | Q1: Deseasonalized SKU-1003 | R1: Deseasonalized SKU-1004 | S1: Deseasonalized SKU-1005 | T1: MEAN SKU-1001 | U1: MEAN SKU-1002 | V1: MEAN SKU-1003 | W1: MEAN SKU-1004 | X1: MEAN SKU-1005
A2: 44927 | B2: 2023 | C2: 1 | D2: 52 | E2: 410 | F2: 266 | G2: 412 | H2: 180 | I2: 189 | J2: =(AVERAGEIFS($E$2:$E$105,$D$2:$D$105,D2))/$T$2 -> 0.76351801 | K2: =(AVERAGEIFS($F$2:$F$105,$D$2:$D$105,D2)/$U$2) -> 1.1052575 | L2: =(AVERAGEIFS($G$2:$G$105,$D$2:$D$105,D2)/$V$2) -> 1.1229262 | M2: =AVERAGEIFS($H$2:$H$105,$D$2:$D$105,D2)/$W$2 -> 1.2350572 | N2: =AVERAGEIFS($I$2:$I$105,$D$2:$D$105,D2)/$X$2 -> 1.3286855 | O2: =D2/J2 -> 68.105793 | P2: =D2/K2 -> 47.047859 | Q2: =D2/L2 -> 46.307586 | R2: =D2/N2 -> 39.136426 | S2: =D2/N2 -> 39.136426 | T2: =AVERAGE(E2:E105) -> 519.96154 | U2: =AVERAGE(F2:F105) -> 359.19231 | V2: =AVERAGE(G2:G105) -> 322.81731 | W2: =AVERAGE(H2:H105) -> 207.68269 | X2: =AVERAGE(I2:I105) -> 275.83654
A3: 44934 | B3: 2023 | C3: 1 | D3: 1 | E3: 356 | F3: 230 | G3: 249 | H3: 48 | I3: 160 | J3: =(AVERAGEIFS($E$2:$E$105,$D$2:$D$105,D3))/$T$2 -> 0.802944 | K3: =(AVERAGEIFS($F$2:$F$105,$D$2:$D$105,D3)/$U$2) -> 0.68626191 | L3: =(AVERAGEIFS($G$2:$G$105,$D$2:$D$105,D3)/$V$2) -> 0.96803979 | M3: =AVERAGEIFS($H$2:$H$105,$D$2:$D$105,D3)/$W$2 -> 0.56817445 | N3: =AVERAGEIFS($I$2:$I$105,$D$2:$D$105,D3)/$X$2 -> 0.70512776 | O3: =D3/J3 -> 1.2454169 | P3: =D3/K3 -> 1.4571696 | Q3: =D3/L3 -> 1.0330154 | R3: =D3/N3 -> 1.4181827 | S3: =D3/N3 -> 1.4181827
A4: 44941 | B4: 2023 | C4: 1 | D4: 2 | E4: 348 | F4: 364 | G4: 267 | H4: 132 | I4: 317 | J4: =(AVERAGEIFS($E$2:$E$105,$D$2:$D$105,D4))/$T$2 -> 0.92506842 | K4: =(AVERAGEIFS($F$2:$F$105,$D$2:$D$105,D4)/$U$2) -> 0.61944534 | L4: =(AVERAGEIFS($G$2:$G$105,$D$2:$D$105,D4)/$V$2) -> 0.82089775 | M4: =AVERAGEIFS($H$2:$H$105,$D$2:$D$105,D4)/$W$2 -> 0.65003009 | N4: =AVERAGEIFS($I$2:$I$105,$D$2:$D$105,D4)/$X$2 -> 0.92264789 | O4: =D4/J4 -> 2.1620022 | P4: =D4/K4 -> 3.2286949 | Q4: =D4/L4 -> 2.436357 | R4: =D4/N4 -> 2.1676742 | S4: =D4/N4 -> 2.1676742
A5: 44948 | B5: 2023 | C5: 1 | D5: 3 | E5: 550 | F5: 212 | G5: 212 | H5: 237 | I5: 192 | J5: =(AVERAGEIFS($E$2:$E$105,$D$2:$D$105,D5))/$T$2 -> 0.83467712 | K5: =(AVERAGEIFS($F$2:$F$105,$D$2:$D$105,D5)/$U$2) -> 0.56933291 | L5: =(AVERAGEIFS($G$2:$G$105,$D$2:$D$105,D5)/$V$2) -> 0.81470229 | M5: =AVERAGEIFS($H$2:$H$105,$D$2:$D$105,D5)/$W$2 -> 0.97745266 | N5: =AVERAGEIFS($I$2:$I$105,$D$2:$D$105,D5)/$X$2 -> 0.48398229 | O5: =D5/J5 -> 3.5942042 | P5: =D5/K5 -> 5.2693248 | Q5: =D5/L5 -> 3.6823267 | R5: =D5/N5 -> 6.1985739 | S5: =D5/N5 -> 6.1985739
A6: 44955 | B6: 2023 | C6: 1 | D6: 4 | E6: 443 | F6: 311 | G6: 250 | H6: 185 | I6: 229 | J6: =(AVERAGEIFS($E$2:$E$105,$D$2:$D$105,D6))/$T$2 -> 0.83179229 | K6: =(AVERAGEIFS($F$2:$F$105,$D$2:$D$105,D6)/$U$2) -> 0.8477353 | L6: =(AVERAGEIFS($G$2:$G$105,$D$2:$D$105,D6)/$V$2) -> 0.77752956 | M6: =AVERAGEIFS($H$2:$H$105,$D$2:$D$105,D6)/$W$2 -> 1.0496782 | N6: =AVERAGEIFS($I$2:$I$105,$D$2:$D$105,D6)/$X$2 -> 0.81570049 | O6: =D6/J6 -> 4.8088928 | P6: =D6/K6 -> 4.718454 | Q6: =D6/L6 -> 5.1444989 | R6: =D6/N6 -> 4.9037607 | S6: =D6/N6 -> 4.9037607
A7: 44962 | B7: 2023 | C7: 2 | D7: 5 | E7: 761 | F7: 339 | G7: 346 | H7: 193 | I7: 230 | J7: =(AVERAGEIFS($E$2:$E$105,$D$2:$D$105,D7))/$T$2 -> 1.1212368 | K7: =(AVERAGEIFS($F$2:$F$105,$D$2:$D$105,D7)/$U$2) -> 0.96048828 | L7: =(AVERAGEIFS($G$2:$G$105,$D$2:$D$105,D7)/$V$2) -> 1.0609716 | M7: =AVERAGEIFS($H$2:$H$105,$D$2:$D$105,D7)/$W$2 -> 0.56817445 | N7: =AVERAGEIFS($I$2:$I$105,$D$2:$D$105,D7)/$X$2 -> 0.78669781 | O7: =D7/J7 -> 4.4593614 | P7: =D7/K7 -> 5.2056856 | Q7: =D7/L7 -> 4.7126614 | R7: =D7/N7 -> 6.3556806 | S7: =D7/N7 -> 6.3556806
A8: 44969 | B8: 2023 | C8: 2 | D8: 6 | E8: 553 | F8: 296 | G8: 320 | H8: 200 | I8: 216 | J8: =(AVERAGEIFS($E$2:$E$105,$D$2:$D$105,D8))/$T$2 -> 1.0019972 | K8: =(AVERAGEIFS($F$2:$F$105,$D$2:$D$105,D8)/$U$2) -> 0.82963915 | L8: =(AVERAGEIFS($G$2:$G$105,$D$2:$D$105,D8)/$V$2) -> 0.88595002 | M8: =AVERAGEIFS($H$2:$H$105,$D$2:$D$105,D8)/$W$2 -> 1.0400482 | N8: =AVERAGEIFS($I$2:$I$105,$D$2:$D$105,D8)/$X$2 -> 0.95165057 | O8: =D8/J8 -> 5.9880407 | P8: =D8/K8 -> 7.2320599 | Q8: =D8/L8 -> 6.7723911 | R8: =D8/N8 -> 6.3048352 | S8: =D8/N8 -> 6.3048352
A9: 44976 | B9: 2023 | C9: 2 | D9: 7 | E9: 430 | F9: 322 | G9: 380 | H9: 186 | I9: 256 | J9: =(AVERAGEIFS($E$2:$E$105,$D$2:$D$105,D9))/$T$2 -> 0.91929876 | K9: =(AVERAGEIFS($F$2:$F$105,$D$2:$D$105,D9)/$U$2) -> 1.1010815 | L9: =(AVERAGEIFS($G$2:$G$105,$D$2:$D$105,D9)/$V$2) -> 1.2220534 | M9: =AVERAGEIFS($H$2:$H$105,$D$2:$D$105,D9)/$W$2 -> 0.92930228 | N9: =AVERAGEIFS($I$2:$I$105,$D$2:$D$105,D9)/$X$2 -> 1.0459093 | O9: =D9/J9 -> 7.6144995 | P9: =D9/K9 -> 6.357386 | Q9: =D9/L9 -> 5.7280638 | R9: =D9/N9 -> 6.692741 | S9: =D9/N9 -> 6.692741
A10: 44983 | B10: 2023 | C10: 2 | D10: 8 | E10: 96 | F10: 321 | G10: 383 | H10: 200 | I10: 283 | J10: =(AVERAGEIFS($E$2:$E$105,$D$2:$D$105,D10))/$T$2 -> 0.59427472 | K10: =(AVERAGEIFS($F$2:$F$105,$D$2:$D$105,D10)/$U$2) -> 0.9869365 | L10: =(AVERAGEIFS($G$2:$G$105,$D$2:$D$105,D10)/$V$2) -> 1.0470318 | M10: =AVERAGEIFS($H$2:$H$105,$D$2:$D$105,D10)/$W$2 -> 1.0111579 | N10: =AVERAGEIFS($I$2:$I$105,$D$2:$D$105,D10)/$X$2 -> 1.0114686 | O10: =D10/J10 -> 13.461787 | P10: =D10/K10 -> 8.1058913 | Q10: =D10/L10 -> 7.6406463 | R10: =D10/N10 -> 7.9092914 | S10: =D10/N10 -> 7.9092914
A11: 44990 | B11: 2023 | C11: 3 | D11: 9 | E11: 505 | F11: 491 | G11: 375 | H11: 58 | I11: 223 | J11: =(AVERAGEIFS($E$2:$E$105,$D$2:$D$105,D11))/$T$2 -> 1.0183446 | K11: =(AVERAGEIFS($F$2:$F$105,$D$2:$D$105,D11)/$U$2) -> 1.1859942 | L11: =(AVERAGEIFS($G$2:$G$105,$D$2:$D$105,D11)/$V$2) -> 0.72177047 | M11: =AVERAGEIFS($H$2:$H$105,$D$2:$D$105,D11)/$W$2 -> 0.54409926 | N11: =AVERAGEIFS($I$2:$I$105,$D$2:$D$105,D11)/$X$2 -> 0.93714923 | O11: =D11/J11 -> 8.8378732 | P11: =D11/K11 -> 7.5885699 | Q11: =D11/L11 -> 12.469338 | R11: =D11/N11 -> 9.6035932 | S11: =D11/N11 -> 9.6035932
A12: 44997 | B12: 2023 | C12: 3 | D12: 10 | E12: 382 | F12: 346 | G12: 249 | H12: 182 | I12: 250 | J12: =(AVERAGEIFS($E$2:$E$105,$D$2:$D$105,D12))/$T$2 -> 0.82794585 | K12: =(AVERAGEIFS($F$2:$F$105,$D$2:$D$105,D12)/$U$2) -> 1.1456259 | L12: =(AVERAGEIFS($G$2:$G$105,$D$2:$D$105,D12)/$V$2) -> 0.98817502 | M12: =AVERAGEIFS($H$2:$H$105,$D$2:$D$105,D12)/$W$2 -> 0.90041206 | N12: =AVERAGEIFS($I$2:$I$105,$D$2:$D$105,D12)/$X$2 -> 0.90089588 | O12: =D12/J12 -> 12.078085 | P12: =D12/K12 -> 8.7288532 | Q12: =D12/L12 -> 10.119665 | R12: =D12/N12 -> 11.100062 | S12: =D12/N12 -> 11.100062
A13: 45004 | B13: 2023 | C13: 3 | D13: 11 | E13: 761 | F13: 336 | G13: 316 | H13: 199 | I13: 255 | J13: =(AVERAGEIFS($E$2:$E$105,$D$2:$D$105,D13))/$T$2 -> 1.1606628 | K13: =(AVERAGEIFS($F$2:$F$105,$D$2:$D$105,D13)/$U$2) -> 0.61387729 | L13: =(AVERAGEIFS($G$2:$G$105,$D$2:$D$105,D13)/$V$2) -> 0.64587615 | M13: =AVERAGEIFS($H$2:$H$105,$D$2:$D$105,D13)/$W$2 -> 0.9702301 | N13: =AVERAGEIFS($I$2:$I$105,$D$2:$D$105,D13)/$X$2 -> 0.99696727 | O13: =D13/J13 -> 9.4773437 | P13: =D13/K13 -> 17.918891 | Q13: =D13/L13 -> 17.031129 | R13: =D13/N13 -> 11.033462 | S13: =D13/N13 -> 11.033462
A14: 45011 | B14: 2023 | C14: 3 | D14: 12 | E14: 665 | F14: 289 | G14: 232 | H14: 211 | I14: 277 | J14: =(AVERAGEIFS($E$2:$E$105,$D$2:$D$105,D14))/$T$2 -> 1.0635402 | K14: =(AVERAGEIFS($F$2:$F$105,$D$2:$D$105,D14)/$U$2) -> 0.97580041 | L14: =(AVERAGEIFS($G$2:$G$105,$D$2:$D$105,D14)/$V$2) -> 0.78992047 | M14: =AVERAGEIFS($H$2:$H$105,$D$2:$D$105,D14)/$W$2 -> 1.1002361 | N14: =AVERAGEIFS($I$2:$I$105,$D$2:$D$105,D14)/$X$2 -> 0.87008052 | O14: =D14/J14 -> 11.283071 | P14: =D14/K14 -> 12.297597 | Q14: =D14/L14 -> 15.191403 | R14: =D14/N14 -> 13.791827 | S14: =D14/N14 -> 13.791827
... A105: 45648 | B105: 2024 | C105: 12 | D105: 51 | E105: 723 | F105: 409 | G105: 407 | H105: 383 | I105: 612 | J105: =(AVERAGEIFS($E$2:$E$105,$D$2:$D$105,D105))/$T$2 -> 1.20682 | K105: =(AVERAGEIFS($F$2:$F$105,$D$2:$D$105,D105)/$U$2) -> 1.2013064 | L105: =(AVERAGEIFS($G$2:$G$105,$D$2:$D$105,D105)/$V$2) -> 1.2421887 | M105: =AVERAGEIFS($H$2:$H$105,$D$2:$D$105,D105)/$W$2 -> 1.5672948 | N105: =AVERAGEIFS($I$2:$I$105,$D$2:$D$105,D105)/$X$2 -> 1.674905 | O105: =D105/J105 -> 42.259822 | P105: =D105/K105 -> 42.453784 | Q105: =D105/L105 -> 41.056565 | R105: =D105/N105 -> 30.449488 | S105: =D105/N105 -> 30.449488
A108: Date | B108: Year | C108: Month | D108: Week | E108: 4WKAVG SKU-1001 | F108: 4WKAVG SKU-1002 | G108: 4WKAVG SKU-1003 | H108: 4WKAVG SKU-1004 | I108: 4WKAVG SKU-1005 | J108: Forecast SKU-1001 | K108: Forecast SKU-1002 | L108: Forecast SKU-1003 | M108: Forecast SKU-1004 | N108: Forecast SKU-1005 | O108: Forecast Deseasonalized SKU-1001 | P108: Forecast Deseasonalized SKU-1002 | Q108: Forecast Deseasonalized SKU-1003 | R108: Forecast Deseasonalized SKU-1004 | S108: Forecast Deseasonalized SKU-1005
A109: 45655 | B109: 2025 | C109: 12 | D109: =MOD(ISOWEEKNUM(A109)-1,52)+1 -> 52 | E109: =AVERAGE(E102:E105) -> 718 | F109: =AVERAGE(F102:F105) -> 480.5 | G109: =AVERAGE(G102:G105) -> 395.25 | H109: =AVERAGE(H102:H105) -> 308.5 | I109: =AVERAGE(I102:I105) -> 457.5 | J109: {=TREND(E2:E105,A2:A105,A109:A121)} -> 576.44231 | K109: {=TREND(F2:F105,A2:A105,A109:A121)} -> 415.83999 | L109: {=TREND(G2:G105,A2:A105,A109:A121)} -> 359.14078 | M109: {=TREND(H2:H105,A2:A105,A109:A121)} -> 245.5829 | N109: {=TREND(I2:I105,A2:A105,A109:A121)} -> 329.1938 | O109: {=TREND(O2:O105,A2:A105,A109:A121)} -> 35.745278 | P109: {=TREND(P2:P105,A2:A105,A109:A121)} -> 34.88851 | Q109: {=TREND(Q2:Q105,A2:A105,A109:A121)} -> 35.888901 | R109: {=TREND(R2:R105,A2:A105,A109:A121)} -> 35.196727 | S109: {=TREND(S2:S105,A2:A105,A109:A121)} -> 35.196727
A110: 45662 | B110: 2025 | C110: 1 | D110: =MOD(ISOWEEKNUM(A110)-1,52)+1 -> 1 | E110: =AVERAGE(E103:E109) -> 691.25 | F110: =AVERAGE(F103:F109) -> 505.625 | G110: =AVERAGE(G103:G109) -> 407.5625 | H110: =AVERAGE(H103:H109) -> 337.875 | I110: =AVERAGE(I103:I109) -> 481.875 | J110: 577.51813 | K110: 416.919 | L110: 359.83265 | M110: 246.30481 | N110: 330.21013 | O110: 35.919701 | P110: 35.059136 | Q110: 36.067897 | R110: 35.373242 | S110: 35.373242
A111: 45669 | B111: 2025 | C111: 1 | D111: =MOD(ISOWEEKNUM(A111)-1,52)+1 -> 2 | E111: =AVERAGE(E104:E110) -> 699.5625 | F111: =AVERAGE(F104:F110) -> 482.28125 | G111: =AVERAGE(G104:G110) -> 389.95312 | H111: =AVERAGE(H104:H110) -> 351.59375 | I111: =AVERAGE(I104:I110) -> 477.84375 | J111: 578.59396 | K111: 417.998 | L111: 360.52453 | M111: 247.02672 | N111: 331.22646 | O111: 36.094123 | P111: 35.229761 | Q111: 36.246894 | R111: 35.549756 | S111: 35.549756
A112: 45676 | B112: 2025 | C112: 1 | D112: =MOD(ISOWEEKNUM(A112)-1,52)+1 -> 3 | E112: =AVERAGE(E105:E111) -> 707.95312 | F112: =AVERAGE(F105:F111) -> 469.35156 | G112: =AVERAGE(G105:G111) -> 399.94141 | H112: =AVERAGE(H105:H111) -> 345.24219 | I112: =AVERAGE(I105:I111) -> 507.30469 | J112: 579.66978 | K112: 419.077 | L112: 361.2164 | M112: 247.74862 | N112: 332.24279 | O112: 36.268546 | P112: 35.400387 | Q112: 36.42589 | R112: 35.726271 | S112: 35.726271
A113: 45683 | B113: 2025 | C113: 1 | D113: =MOD(ISOWEEKNUM(A113)-1,52)+1 -> 4 | E113: =AVERAGE(E109:E112) -> 704.19141 | F113: =AVERAGE(F109:F112) -> 484.43945 | G113: =AVERAGE(G109:G112) -> 398.17676 | H113: =AVERAGE(H109:H112) -> 335.80273 | I113: =AVERAGE(I109:I112) -> 481.13086 | J113: 580.7456 | K113: 420.15601 | L113: 361.90828 | M113: 248.47053 | N113: 333.25912 | O113: 36.442969 | P113: 35.571013 | Q113: 36.604886 | R113: 35.902785 | S113: 35.902785
A114: 45690 | B114: 2025 | C114: 2 | D114: =MOD(ISOWEEKNUM(A114)-1,52)+1 -> 5 | E114: =AVERAGE(E110:E113) -> 700.73926 | F114: =AVERAGE(F110:F113) -> 485.42432 | G114: =AVERAGE(G110:G113) -> 398.90845 | H114: =AVERAGE(H110:H113) -> 342.62842 | I114: =AVERAGE(I110:I113) -> 487.03857 | J114: 581.82143 | K114: 421.23501 | L114: 362.60015 | M114: 249.19244 | N114: 334.27545 | O114: 36.617391 | P114: 35.741639 | Q114: 36.783883 | R114: 36.0793 | S114: 36.0793
A115: 45697 | B115: 2025 | C115: 2 | D115: =MOD(ISOWEEKNUM(A115)-1,52)+1 -> 6 | E115: =AVERAGE(E111:E114) -> 703.11157 | F115: =AVERAGE(F111:F114) -> 480.37415 | G115: =AVERAGE(G111:G114) -> 396.74493 | H115: =AVERAGE(H111:H114) -> 343.81677 | I115: =AVERAGE(I111:I114) -> 488.32947 | J115: 582.89725 | K115: 422.31401 | L115: 363.29203 | M115: 249.91435 | N115: 335.29177 | O115: 36.791814 | P115: 35.912265 | Q115: 36.962879 | R115: 36.255814 | S115: 36.255814
A116: 45704 | B116: 2025 | C116: 2 | D116: =MOD(ISOWEEKNUM(A116)-1,52)+1 -> 7 | E116: =AVERAGE(E112:E115) -> 703.99884 | F116: =AVERAGE(F112:F115) -> 479.89737 | G116: =AVERAGE(G112:G115) -> 398.44289 | H116: =AVERAGE(H112:H115) -> 341.87253 | I116: =AVERAGE(I112:I115) -> 490.9509 | J116: 583.97308 | K116: 423.39302 | L116: 363.98391 | M116: 250.63626 | N116: 336.3081 | O116: 36.966236 | P116: 36.082891 | Q116: 37.141875 | R116: 36.432329 | S116: 36.432329
A117: 45711 | B117: 2025 | C117: 2 | D117: =MOD(ISOWEEKNUM(A117)-1,52)+1 -> 8 | E117: =AVERAGE(E113:E116) -> 703.01027 | F117: =AVERAGE(F113:F116) -> 482.53382 | G117: =AVERAGE(G113:G116) -> 398.06826 | H117: =AVERAGE(H113:H116) -> 341.03011 | I117: =AVERAGE(I113:I116) -> 486.86245 | J117: 585.0489 | K117: 424.47202 | L117: 364.67578 | M117: 251.35817 | N117: 337.32443 | O117: 37.140659 | P117: 36.253517 | Q117: 37.320872 | R117: 36.608843 | S117: 36.608843
A118: 45718 | B118: 2025 | C118: 3 | D118: =MOD(ISOWEEKNUM(A118)-1,52)+1 -> 9 | E118: =AVERAGE(E114:E117) -> 702.71498 | F118: =AVERAGE(F114:F117) -> 482.05741 | G118: =AVERAGE(G114:G117) -> 398.04113 | H118: =AVERAGE(H114:H117) -> 342.33696 | I118: =AVERAGE(I114:I117) -> 488.29535 | J118: 586.12473 | K118: 425.55102 | L118: 365.36766 | M118: 252.08008 | N118: 338.34076 | O118: 37.315082 | P118: 36.424143 | Q118: 37.499868 | R118: 36.785358 | S118: 36.785358
A119: 45725 | B119: 2025 | C119: 3 | D119: =MOD(ISOWEEKNUM(A119)-1,52)+1 -> 10 | E119: =AVERAGE(E115:E118) -> 703.20892 | F119: =AVERAGE(F115:F118) -> 481.21569 | G119: =AVERAGE(G115:G118) -> 397.8243 | H119: =AVERAGE(H115:H118) -> 342.26409 | I119: =AVERAGE(I115:I118) -> 488.60954 | J119: 587.20055 | K119: 426.63003 | L119: 366.05953 | M119: 252.80198 | N119: 339.35709 | O119: 37.489504 | P119: 36.594769 | Q119: 37.678864 | R119: 36.961872 | S119: 36.961872
A120: 45732 | B120: 2025 | C120: 3 | D120: =MOD(ISOWEEKNUM(A120)-1,52)+1 -> 11 | E120: =AVERAGE(E116:E119) -> 703.23325 | F120: =AVERAGE(F116:F119) -> 481.42607 | G120: =AVERAGE(G116:G119) -> 398.09414 | H120: =AVERAGE(H116:H119) -> 341.87592 | I120: =AVERAGE(I116:I119) -> 488.67956 | J120: 588.27637 | K120: 427.70903 | L120: 366.75141 | M120: 253.52389 | N120: 340.37342 | O120: 37.663927 | P120: 36.765395 | Q120: 37.857861 | R120: 37.138387 | S120: 37.138387
A121: 45739 | B121: 2025 | C121: 3 | D121: =MOD(ISOWEEKNUM(A121)-1,52)+1 -> 12 | E121: =AVERAGE(E117:E120) -> 703.04186 | F121: =AVERAGE(F117:F120) -> 481.80825 | G121: =AVERAGE(G117:G120) -> 398.00696 | H121: =AVERAGE(H117:H120) -> 341.87677 | I121: =AVERAGE(I117:I120) -> 488.11172 | J121: 589.3522 | K121: 428.78803 | L121: 367.44328 | M121: 254.2458 | N121: 341.38975 | O121: 37.838349 | P121: 36.936021 | Q121: 38.036857 | R121: 37.314901 | S121: 37.314901

Sheet PHASE 3
A1: Date | B1: Year | C1: Month | D1: Week | E1: Actual Demand SKU-1001 | F1: Actual Demand SKU-1002 | G1: Actual Demand SKU-1003 | H1: Actual Demand SKU-1004 | I1: Actual Demand SKU-1005 | J1: Forecast SKU-1001 | K1: Forecast SKU-1002 | L1: Forecast SKU-1003 | M1: Forecast SKU-1004 | N1: Forecast SKU-1005 | O1: Absolute percentage error SKU-1001 | P1: Absolute percentage error SKU-1002 | Q1: Absolute percentage error SKU-1003 | R1: Absolute percentage error SKU-1004 | S1: Absolute percentage error SKU-1005
A2: 45655 | B2: 2025 | C2: 12 | D2: =MOD(ISOWEEKNUM(A2)-1,52)+1 -> 52 | E2: 659 | F2: 402 | G2: 417 | H2: 230 | I2: 382 | J2: 576.44231 | K2: 415.83999 | L2: 359.14078 | M2: 245.5829 | N2: 329.1938 | O2: =ABS((E2-J2)/E2) -> 0.12527723 | P2: =ABS((F2-K2)/F2) -> 0.034427842 | Q2: =ABS((G2-L2)/G2) -> 0.13875113 | R2: =ABS((H2-M2)/H2) -> 0.067751729 | S2: =ABS((I2-N2)/I2) -> 0.13823612
A3: 45662 | B3: 2025 | C3: 1 | D3: =MOD(ISOWEEKNUM(A3)-1,52)+1 -> 1 | E3: 435 | F3: 334 | G3: 314 | H3: 250 | I3: 223 | J3: 577.51813 | K3: 416.919 | L3: 359.83265 | M3: 246.30481 | N3: 330.21013 | O3: =ABS((E3-J3)/E3) -> 0.32762789 | P3: =ABS((F3-K3)/F3) -> 0.24826047 | Q3: =ABS((G3-L3)/G3) -> 0.14596386 | R3: =ABS((H3-M3)/H3) -> 0.014780775 | S3: =ABS((I3-N3)/I3) -> 0.48076292
A4: 45669 | B4: 2025 | C4: 1 | D4: =MOD(ISOWEEKNUM(A4)-1,52)+1 -> 2 | E4: 475 | F4: 318 | G4: 320 | H4: 300 | I4: 315 | J4: 578.59396 | K4: 417.998 | L4: 360.52453 | M4: 247.02672 | N4: 331.22646 | O4: =ABS((E4-J4)/E4) -> 0.21809254 | P4: =ABS((F4-K4)/F4) -> 0.31445912 | Q4: =ABS((G4-L4)/G4) -> 0.12663915 | R4: =ABS((H4-M4)/H4) -> 0.17657762 | S4: =ABS((I4-N4)/I4) -> 0.051512568
A5: 45676 | B5: 2025 | C5: 1 | D5: =MOD(ISOWEEKNUM(A5)-1,52)+1 -> 3 | E5: 495 | F5: 352 | G5: 249 | H5: 186 | I5: 236 | J5: 579.66978 | K5: 419.077 | L5: 361.2164 | M5: 247.74862 | N5: 332.24279 | O5: =ABS((E5-J5)/E5) -> 0.17105006 | P5: =ABS((F5-K5)/F5) -> 0.19055967 | Q5: =ABS((G5-L5)/G5) -> 0.45066829 | R5: =ABS((H5-M5)/H5) -> 0.33198185 | S5: =ABS((I5-N5)/I5) -> 0.40780842
A6: 45683 | B6: 2025 | C6: 1 | D6: =MOD(ISOWEEKNUM(A6)-1,52)+1 -> 4 | E6: 513 | F6: 383 | G6: 455 | H6: 238 | I6: 349 | J6: 580.7456 | K6: 420.15601 | L6: 361.90828 | M6: 248.47053 | N6: 333.25912 | O6: =ABS((E6-J6)/E6) -> 0.13205771 | P6: =ABS((F6-K6)/F6) -> 0.097013072 | Q6: =ABS((G6-L6)/G6) -> 0.20459719 | R6: =ABS((H6-M6)/H6) -> 0.043993834 | S6: =ABS((I6-N6)/I6) -> 0.045102818
A7: 45690 | B7: 2025 | C7: 2 | D7: =MOD(ISOWEEKNUM(A7)-1,52)+1 -> 5 | E7: 585 | F7: 589 | G7: 449 | H7: 489 | I7: 324 | J7: 581.82143 | K7: 421.23501 | L7: 362.60015 | M7: 249.19244 | N7: 334.27545 | O7: =ABS((E7-J7)/E7) -> 0.0054334554 | P7: =ABS((F7-K7)/F7) -> 0.2848302 | Q7: =ABS((G7-L7)/G7) -> 0.19242727 | R7: =ABS((H7-M7)/H7) -> 0.49040401 | S7: =ABS((I7-N7)/I7) -> 0.031714338
A8: 45697 | B8: 2025 | C8: 2 | D8: =MOD(ISOWEEKNUM(A8)-1,52)+1 -> 6 | E8: 790 | F8: 490 | G8: 317 | H8: 333 | I8: 290 | J8: 582.89725 | K8: 422.31401 | L8: 363.29203 | M8: 249.91435 | N8: 335.29177 | O8: =ABS((E8-J8)/E8) -> 0.26215538 | P8: =ABS((F8-K8)/F8) -> 0.13813467 | Q8: =ABS((G8-L8)/G8) -> 0.14603164 | R8: =ABS((H8-M8)/H8) -> 0.24950646 | S8: =ABS((I8-N8)/I8) -> 0.15617853
A9: 45704 | B9: 2025 | C9: 2 | D9: =MOD(ISOWEEKNUM(A9)-1,52)+1 -> 7 | E9: 596 | F9: 470 | G9: 595 | H9: 221 | I9: 413 | J9: 583.97308 | K9: 423.39302 | L9: 363.98391 | M9: 250.63626 | N9: 336.3081 | O9: =ABS((E9-J9)/E9) -> 0.020179401 | P9: =ABS((F9-K9)/F9) -> 0.099163793 | Q9: =ABS((G9-L9)/G9) -> 0.38826234 | R9: =ABS((H9-M9)/H9) -> 0.13410072 | S9: =ABS((I9-N9)/I9) -> 0.18569467
A10: 45711 | B10: 2025 | C10: 2 | D10: =MOD(ISOWEEKNUM(A10)-1,52)+1 -> 8 | E10: 728 | F10: 561 | G10: 593 | H10: 287 | I10: 487 | J10: 585.0489 | K10: 424.47202 | L10: 364.67578 | M10: 251.35817 | N10: 337.32443 | O10: =ABS((E10-J10)/E10) -> 0.1963614 | P10: =ABS((F10-K10)/F10) -> 0.24336538 | Q10: =ABS((G10-L10)/G10) -> 0.38503241 | R10: =ABS((H10-M10)/H10) -> 0.12418757 | S10: =ABS((I10-N10)/I10) -> 0.30734203
A11: 45718 | B11: 2025 | C11: 3 | D11: =MOD(ISOWEEKNUM(A11)-1,52)+1 -> 9 | E11: 825 | F11: 380 | G11: 346 | H11: 191 | I11: 360 | J11: 586.12473 | K11: 425.55102 | L11: 365.36766 | M11: 252.08008 | N11: 338.34076 | O11: =ABS((E11-J11)/E11) -> 0.28954579 | P11: =ABS((F11-K11)/F11) -> 0.11987112 | Q11: =ABS((G11-L11)/G11) -> 0.055975888 | R11: =ABS((H11-M11)/H11) -> 0.31979097 | S11: =ABS((I11-N11)/I11) -> 0.060164554
A12: 45725 | B12: 2025 | C12: 3 | D12: =MOD(ISOWEEKNUM(A12)-1,52)+1 -> 10 | E12: 658 | F12: 599 | G12: 478 | H12: 283 | I12: 498 | J12: 587.20055 | K12: 426.63003 | L12: 366.05953 | M12: 252.80198 | N12: 339.35709 | O12: =ABS((E12-J12)/E12) -> 0.10759795 | P12: =ABS((F12-K12)/F12) -> 0.28776289 | Q12: =ABS((G12-L12)/G12) -> 0.23418508 | R12: =ABS((H12-M12)/H12) -> 0.10670677 | S12: =ABS((I12-N12)/I12) -> 0.31856006
A13: 45732 | B13: 2025 | C13: 3 | D13: =MOD(ISOWEEKNUM(A13)-1,52)+1 -> 11 | E13: 666 | F13: 534 | G13: 350 | H13: 377 | I13: 360 | J13: 588.27637 | K13: 427.70903 | L13: 366.75141 | M13: 253.52389 | N13: 340.37342 | O13: =ABS((E13-J13)/E13) -> 0.11670214 | P13: =ABS((F13-K13)/F13) -> 0.19904676 | Q13: =ABS((G13-L13)/G13) -> 0.047861167 | R13: =ABS((H13-M13)/H13) -> 0.32752283 | S13: =ABS((I13-N13)/I13) -> 0.054518282
A14: 45739 | B14: 2025 | C14: 3 | D14: =MOD(ISOWEEKNUM(A14)-1,52)+1 -> 12 | E14: 723 | F14: 409 | G14: 407 | H14: 383 | I14: 612 | J14: 589.3522 | K14: 428.78803 | L14: 367.44328 | M14: 254.2458 | N14: 341.38975 | O14: =ABS((E14-J14)/E14) -> 0.18485173 | P14: =ABS((F14-K14)/F14) -> 0.048381503 | Q14: =ABS((G14-L14)/G14) -> 0.097190949 | R14: =ABS((H14-M14)/H14) -> 0.33617284 | S14: =ABS((I14-N14)/I14) -> 0.44217362
A18: SKU | B18: MAPE | C18: Frecast Accuracy
A19: SKU-1001 | B19: =AVERAGE(O2:O14) -> 0.1659179 | C19: =1-B19 -> 0.8340821
A20: SKU-1002 | B20: =AVERAGE(P2:P14) -> 0.17732896 | C20: =1-B20 -> 0.82267104
A21: SKU-1003 | B21: =AVERAGE(Q2:Q14) -> 0.20104511 | C21: =1-B21 -> 0.79895489
A22: SKU-1004 | B22: =AVERAGE(R2:R14) -> 0.2094983 | C22: =1-B22 -> 0.7905017
A23: SKU-1005 | B23: =AVERAGE(S2:S14) -> 0.20613607 | C23: =1-B23 -> 0.79386393

Sheet PHASE 4
A1: Sales by Month | D1: Sales by SKU and Year | I1: Promo vs Non-Promo Performance
